<?xml version="1.0" ?>
<robot name="fanuc_m16ib">

  <link name="base_link">
    <visual>
      <origin xyz="0 0 0" rpy="0 0 0"/>
      <geometry>
        <mesh filename="package://manufacturing_os_description/meshes/fanuc_m16ib/visual/base_link.stl"/>
      </geometry>
      <material name="fanuc_yellow">
        <color rgba="0.96 0.76 0.13 1.0"/>
      </material>
    </visual>
    <collision>
      <origin xyz="0 0 0" rpy="0 0 0"/>
      <geometry>
        <mesh filename="package://manufacturing_os_description/meshes/fanuc_m16ib/collision/base_link.stl"/>
      </geometry>
    </collision>
  </link>

  <link name="link_1">
    <visual>
      <origin xyz="0 0 0" rpy="0 0 0"/>
      <geometry>
        <mesh filename="package://manufacturing_os_description/meshes/fanuc_m16ib/visual/link_1.stl"/>
      </geometry>
      <material name="fanuc_yellow">
        <color rgba="0.96 0.76 0.13 1.0"/>
      </material>
    </visual>
    <collision>
      <origin xyz="0 0 0" rpy="0 0 0"/>
      <geometry>
        <mesh filename="package://manufacturing_os_description/meshes/fanuc_m16ib/collision/link_1.stl"/>
      </geometry>
    </collision>
  </link>

  <link name="link_2">
    <visual>
      <origin xyz="0 0 0" rpy="0 0 0"/>
      <geometry>
        <mesh filename="package://manufacturing_os_description/meshes/fanuc_m16ib/visual/link_2.stl"/>
      </geometry>
      <material name="fanuc_yellow">
        <color rgba="0.96 0.76 0.13 1.0"/>
      </material>
    </visual>
    <collision>
      <origin xyz="0 0 0" rpy="0 0 0"/>
      <geometry>
        <mesh filename="package://manufacturing_os_description/meshes/fanuc_m16ib/collision/link_2.stl"/>
      </geometry>
    </collision>
  </link>

  <link name="link_3">
    <visual>
      <origin xyz="0 0 0" rpy="0 0 0"/>
      <geometry>
        <mesh filename="package://manufacturing_os_description/meshes/fanuc_m16ib/visual/link_3.stl"/>
      </geometry>
      <material name="fanuc_yellow">
        <color rgba="0.96 0.76 0.13 1.0"/>
      </material>
    </visual>
    <collision>
      <origin xyz="0 0 0" rpy="0 0 0"/>
      <geometry>
        <mesh filename="package://manufacturing_os_description/meshes/fanuc_m16ib/collision/link_3.stl"/>
      </geometry>
    </collision>
  </link>

  <link name="link_4">
    <visual>
      <origin xyz="0 0 0" rpy="0 0 0"/>
      <geometry>
        <mesh filename="package://manufacturing_os_description/meshes/fanuc_m16ib/visual/link_4.stl"/>
      </geometry>
      <material name="fanuc_yellow">
        <color rgba="0.96 0.76 0.13 1.0"/>
      </material>
    </visual>
    <collision>
      <origin xyz="0 0 0" rpy="0 0 0"/>
      <geometry>
        <mesh filename="package://manufacturing_os_description/meshes/fanuc_m16ib/collision/link_4.stl"/>
      </geometry>
    </collision>
  </link>

  <link name="link_5">
    <visual>
      <origin xyz="0 0 0" rpy="0 0 0"/>
      <geometry>
        <mesh filename="package://manufacturing_os_description/meshes/fanuc_m16ib/visual/link_5.stl"/>
      </geometry>
      <material name="fanuc_yellow">
        <color rgba="0.96 0.76 0.13 1.0"/>
      </material>
    </visual>
    <collision>
      <origin xyz="0 0 0" rpy="0 0 0"/>
      <geometry>
        <mesh filename="package://manufacturing_os_description/meshes/fanuc_m16ib/collision/link_5.stl"/>
      </geometry>
    </collision>
  </link>

  <link name="link_6">
    <visual>
      <origin xyz="0 0 0" rpy="0 0 0"/>
      <geometry>
        <mesh filename="package://manufacturing_os_description/meshes/fanuc_m16ib/visual/link_6.stl"/>
      </geometry>
      <material name="fanuc_black">
        <color rgba="0.15 0.15 0.15 1.0"/>
      </material>
    </visual>
    <collision>
      <origin xyz="0 0 0" rpy="0 0 0"/>
      <geometry>
        <mesh filename="package://manufacturing_os_description/meshes/fanuc_m16ib/collision/link_6.stl"/>
      </geometry>
    </collision>
  </link>

  <joint name="joint_1" type="revolute">
    <origin xyz="0 0 0.525" rpy="0 0 0"/>
    <parent link="base_link"/>
    <child link="link_1"/>
    <axis xyz="0 0 1"/>
    <limit effort="0" lower="-2.9671" upper="2.9671" velocity="2.8798" />
  </joint>

  <joint name="joint_2" type="revolute">
    <origin xyz="0.150 0 0" rpy="0 0 0"/>
    <parent link="link_1"/>
    <child link="link_2"/>
    <axis xyz="0 1 0"/>
    <limit effort="0" lower="-1.5708" upper="2.7925" velocity="2.8798" />
  </joint>

  <joint name="joint_3" type="revolute">
    <origin xyz="0 0 0.770" rpy="0 0 0"/>
    <parent link="link_2"/>
    <child link="link_3"/>
    <axis xyz="0 -1 0"/>
    <limit effort="0" lower="-2.9671" upper="5.0615" velocity="3.0543" />
  </joint>

  <joint name="joint_4" type="revolute">
    <origin xyz="0 0 0.100" rpy="0 0 0"/>
    <parent link="link_3"/>
    <child link="link_4"/>
    <axis xyz="-1 0 0"/>
    <limit effort="0" lower="-3.4907" upper="3.4907" velocity="6.1087" />
  </joint>

  <joint name="joint_5" type="revolute">
    <origin xyz="0.740 0 0" rpy="0 0 0"/>
    <parent link="link_4"/>
    <child link="link_5"/>
    <axis xyz="0 -1 0"/>
    <limit effort="0" lower="-2.4435" upper="2.4435" velocity="5.9341" />
  </joint>

  <joint name="joint_6" type="revolute">
    <origin xyz="0.100 0 0" rpy="0 0 0"/>
    <parent link="link_5"/>
    <child link="link_6"/>
    <axis xyz="-1 0 0"/>
    <limit effort="0" lower="-7.8540" upper="7.8540" velocity="9.0757" />
  </joint>

  <link name="base" />
  <joint name="base_link-base" type="fixed">
    <origin xyz="0 0 0.525" rpy="0 0 0"/>
    <parent link="base_link"/>
    <child link="base"/>
  </joint>

  <link name="flange" />
  <joint name="joint_6-flange" type="fixed">
    <origin xyz="0 0 0" rpy="0 0 0" />
    <parent link="link_6" />
    <child link="flange" />
  </joint>

  <link name="tool0" />
  <joint name="link_6-tool0" type="fixed">
    <origin xyz="0 0 0" rpy="3.1415926535 -1.57079632679 0" />
    <parent link="flange" />
    <child link="tool0" />
  </joint>
  
  <ros2_control name="FanucM16iB_HardwareInterface" type="system">
    <hardware>
      <plugin>fake_components/GenericSystem</plugin>
    </hardware>

    <joint name="joint_1">
      <command_interface name="position">
        <param name="min">-2.9671</param>
        <param name="max">2.9671</param>
      </command_interface>
      <state_interface name="position">
        <param name="initial_value">0.0</param>
      </state_interface>
      <state_interface name="velocity"/>
    </joint>

    <joint name="joint_2">
      <command_interface name="position">
        <param name="min">-1.5708</param>
        <param name="max">2.7925</param>
      </command_interface>
      <state_interface name="position">
        <param name="initial_value">0.0</param>
      </state_interface>
      <state_interface name="velocity"/>
    </joint>

    <joint name="joint_3">
      <command_interface name="position">
        <param name="min">-2.9671</param>
        <param name="max">5.0615</param>
      </command_interface>
      <state_interface name="position">
        <param name="initial_value">0.0</param>
      </state_interface>
      <state_interface name="velocity"/>
    </joint>

    <joint name="joint_4">
      <command_interface name="position">
        <param name="min">-3.4907</param>
        <param name="max">3.4907</param>
      </command_interface>
      <state_interface name="position">
        <param name="initial_value">0.0</param>
      </state_interface>
      <state_interface name="velocity"/>
    </joint>

    <joint name="joint_5">
      <command_interface name="position">
        <param name="min">-2.4435</param>
        <param name="max">2.4435</param>
      </command_interface>
      <state_interface name="position">
        <param name="initial_value">0.0</param>
      </state_interface>
      <state_interface name="velocity"/>
    </joint>

    <joint name="joint_6">
      <command_interface name="position">
        <param name="min">-7.8540</param>
        <param name="max">7.8540</param>
      </command_interface>
      <state_interface name="position">
        <param name="initial_value">0.0</param>
      </state_interface>
      <state_interface name="velocity"/>
    </joint>

  </ros2_control>
</robot>
