<?xml version="1.0" ?>
<robot name="robot1">
  <material name="yaskawa_blue">
    <color rgba="0.12941 0.14902 0.74902 1.0"/>
  </material>
  
  <link name="world"/>
  <joint name="world_fixed" type="fixed">
    <parent link="world"/>
    <child link="base_link"/>
  </joint>
  
  <link name="base_link">
    <visual>
      <geometry>
        <mesh filename="package://manufacturing_os_description/meshes/visual/gp8_base_link.stl"/>
      </geometry>
      <material name="yaskawa_blue"/>
    </visual>
    <collision>
      <geometry>
        <mesh filename="package://manufacturing_os_description/meshes/collision/gp8_base_link.stl"/>
      </geometry>
    </collision>
    <inertial>
      <mass value="1.0"/>
      <origin rpy="0 0 0" xyz="0 0 0"/>
      <inertia ixx="0.01" ixy="0.0" ixz="0.0" iyy="0.01" iyz="0.0" izz="0.01"/>
    </inertial>
  </link>
  
  <link name="link_1_s">
    <visual>
      <geometry>
        <mesh filename="package://manufacturing_os_description/meshes/visual/gp8_link_1_s.stl"/>
      </geometry>
      <material name="yaskawa_blue"/>
    </visual>
    <collision>
      <geometry>
        <mesh filename="package://manufacturing_os_description/meshes/collision/gp8_link_1_s.stl"/>
      </geometry>
    </collision>
    <inertial>
      <mass value="1.0"/>
      <origin rpy="0 0 0" xyz="0 0 0"/>
      <inertia ixx="0.01" ixy="0.0" ixz="0.0" iyy="0.01" iyz="0.0" izz="0.01"/>
    </inertial>
  </link>
  
  <link name="link_2_l">
    <visual>
      <geometry>
        <mesh filename="package://manufacturing_os_description/meshes/visual/gp8_link_2_l.stl"/>
      </geometry>
      <material name="yaskawa_blue"/>
    </visual>
    <collision>
      <geometry>
        <mesh filename="package://manufacturing_os_description/meshes/collision/gp8_link_2_l.stl"/>
      </geometry>
    </collision>
    <inertial>
      <mass value="1.0"/>
      <origin rpy="0 0 0" xyz="0 0 0"/>
      <inertia ixx="0.01" ixy="0.0" ixz="0.0" iyy="0.01" iyz="0.0" izz="0.01"/>
    </inertial>
  </link>
  
  <link name="link_3_u">
    <visual>
      <geometry>
        <mesh filename="package://manufacturing_os_description/meshes/visual/gp8_link_3_u.stl"/>
      </geometry>
      <material name="yaskawa_blue"/>
    </visual>
    <collision>
      <geometry>
        <mesh filename="package://manufacturing_os_description/meshes/collision/gp8_link_3_u.stl"/>
      </geometry>
    </collision>
    <inertial>
      <mass value="1.0"/>
      <origin rpy="0 0 0" xyz="0 0 0"/>
      <inertia ixx="0.01" ixy="0.0" ixz="0.0" iyy="0.01" iyz="0.0" izz="0.01"/>
    </inertial>
  </link>
  
  <link name="link_4_r">
    <visual>
      <geometry>
        <mesh filename="package://manufacturing_os_description/meshes/visual/gp8_link_4_r.stl"/>
      </geometry>
      <material name="yaskawa_blue"/>
    </visual>
    <collision>
      <geometry>
        <mesh filename="package://manufacturing_os_description/meshes/collision/gp8_link_4_r.stl"/>
      </geometry>
    </collision>
    <inertial>
      <mass value="1.0"/>
      <origin rpy="0 0 0" xyz="0 0 0"/>
      <inertia ixx="0.01" ixy="0.0" ixz="0.0" iyy="0.01" iyz="0.0" izz="0.01"/>
    </inertial>
  </link>
  
  <link name="link_5_b">
    <visual>
      <geometry>
        <mesh filename="package://manufacturing_os_description/meshes/visual/gp8_link_5_b.stl"/>
      </geometry>
      <material name="yaskawa_blue"/>
    </visual>
    <collision>
      <geometry>
        <mesh filename="package://manufacturing_os_description/meshes/collision/gp8_link_5_b.stl"/>
      </geometry>
    </collision>
    <inertial>
      <mass value="1.0"/>
      <origin rpy="0 0 0" xyz="0 0 0"/>
      <inertia ixx="0.01" ixy="0.0" ixz="0.0" iyy="0.01" iyz="0.0" izz="0.01"/>
    </inertial>
  </link>
  
  <link name="link_6_t">
    <visual>
      <geometry>
        <mesh filename="package://manufacturing_os_description/meshes/visual/gp8_link_6_t.stl"/>
      </geometry>
      <material name="yaskawa_blue"/>
    </visual>
    <collision>
      <geometry>
        <mesh filename="package://manufacturing_os_description/meshes/collision/gp8_link_6_t.stl"/>
      </geometry>
    </collision>
    <inertial>
      <mass value="1.0"/>
      <origin rpy="0 0 0" xyz="0 0 0"/>
      <inertia ixx="0.01" ixy="0.0" ixz="0.0" iyy="0.01" iyz="0.0" izz="0.01"/>
    </inertial>
  </link>
  
  <joint name="joint_1_s" type="revolute">
    <parent link="base_link"/>
    <child link="link_1_s"/>
    <origin rpy="0 0 0" xyz="0 0 0.330"/>
    <axis xyz="0 0 1"/>
    <limit effort="150.92" lower="-2.9670597283903604" upper="2.9670597283903604" velocity="7.941248096574199"/>
    <dynamics damping="50.0" friction="50.0"/>
  </joint>
  
  <joint name="joint_2_l" type="revolute">
    <parent link="link_1_s"/>
    <child link="link_2_l"/>
    <origin rpy="0 0 0" xyz="0.040 0 0"/>
    <axis xyz="0 1 0"/>
    <limit effort="176.4" lower="-1.1344640137963142" upper="2.530727415391778" velocity="6.719517620178169"/>
    <dynamics damping="50.0" friction="50.0"/>
  </joint>
  
  <joint name="joint_3_u" type="revolute">
    <parent link="link_2_l"/>
    <child link="link_3_u"/>
    <origin rpy="0 0 0" xyz="0 0 0.345"/>
    <axis xyz="0 -1 0"/>
    <limit effort="107.56" lower="-1.2217304763960306" upper="3.3161255787892263" velocity="9.075712110370514"/>
    <dynamics damping="50.0" friction="50.0"/>
  </joint>
  
  <joint name="joint_4_r" type="revolute">
    <parent link="link_3_u"/>
    <child link="link_4_r"/>
    <origin rpy="0 0 0" xyz="0.340 0 0.040"/>
    <axis xyz="-1 0 0"/>
    <limit effort="55.86" lower="-3.3161255787892263" upper="3.3161255787892263" velocity="9.599310885968812"/>
    <dynamics damping="50.0" friction="50.0"/>
  </joint>
  
  <joint name="joint_5_b" type="revolute">
    <parent link="link_4_r"/>
    <child link="link_5_b"/>
    <origin rpy="0 0 0" xyz="0 0 0"/>
    <axis xyz="0 -1 0"/>
    <limit effort="32.68" lower="-2.356194490192345" upper="2.356194490192345" velocity="9.599310885968812"/>
    <dynamics damping="50.0" friction="50.0"/>
  </joint>
  
  <joint name="joint_6_t" type="revolute">
    <parent link="link_5_b"/>
    <child link="link_6_t"/>
    <origin rpy="0 0 0" xyz="0 0 0"/>
    <axis xyz="-1 0 0"/>
    <limit effort="22.54" lower="-6.283185307179586" upper="6.283185307179586" velocity="17.453292519943297"/>
    <dynamics damping="50.0" friction="50.0"/>
  </joint>
  
  <link name="flange"/>
  <joint name="joint_6_t-flange" type="fixed">
    <origin rpy="0 0 0" xyz="0.080 0 0"/>
    <parent link="link_6_t"/>
    <child link="flange"/>
  </joint>
  
  <link name="tool0"/>
  <joint name="flange-tool0" type="fixed">
    <origin rpy="3.141592653589793 -1.5707963267948966 0" xyz="0 0 0"/>
    <parent link="flange"/>
    <child link="tool0"/>
  </joint>
  
  <link name="base"/>
  <joint name="base_link-base" type="fixed">
    <origin rpy="0 0 0" xyz="0 0 0.330"/>
    <parent link="base_link"/>
    <child link="base"/>
  </joint>
  
  <ros2_control name="GazeboSystemR1" type="system">
    <hardware>
      <plugin>gazebo_ros2_control/GazeboSystem</plugin>
    </hardware>

    <joint name="joint_1_s">
      <command_interface name="position">
        <param name="min">-2.96</param>
        <param name="max">2.96</param>
      </command_interface>
      <state_interface name="position"/>
      <state_interface name="velocity"/>
      <state_interface name="effort"/>
    </joint>

    <joint name="joint_2_l">
      <command_interface name="position">
        <param name="min">-1.13</param>
        <param name="max">2.53</param>
      </command_interface>
      <state_interface name="position"/>
      <state_interface name="velocity"/>
      <state_interface name="effort"/>
    </joint>

    <joint name="joint_3_u">
      <command_interface name="position">
        <param name="min">-1.22</param>
        <param name="max">3.31</param>
      </command_interface>
      <state_interface name="position"/>
      <state_interface name="velocity"/>
      <state_interface name="effort"/>
    </joint>

    <joint name="joint_4_r">
      <command_interface name="position">
        <param name="min">-3.31</param>
        <param name="max">3.31</param>
      </command_interface>
      <state_interface name="position"/>
      <state_interface name="velocity"/>
      <state_interface name="effort"/>
    </joint>

    <joint name="joint_5_b">
      <command_interface name="position">
        <param name="min">-2.35</param>
        <param name="max">2.35</param>
      </command_interface>
      <state_interface name="position"/>
      <state_interface name="velocity"/>
      <state_interface name="effort"/>
    </joint>

    <joint name="joint_6_t">
      <command_interface name="position">
        <param name="min">-6.28</param>
        <param name="max">6.28</param>
      </command_interface>
      <state_interface name="position"/>
      <state_interface name="velocity"/>
      <state_interface name="effort"/>
    </joint>
  </ros2_control>

  <gazebo>
    <plugin filename="libgazebo_ros2_control.so" name="gazebo_ros2_control_r1">
    <ros>
        <namespace>/robot1</namespace>
    </ros>
      <parameters>/home/mekatronik/ManufacturingOS/install/manufacturing_os_description/share/manufacturing_os_description/config/controllers.yaml</parameters>
    </plugin>
  </gazebo>
  
</robot>
